[2024-06-21T20:05:47.276+0000] {taskinstance.py:1159} INFO - Dependencies all met for dep_context=non-requeueable deps ti=<TaskInstance: kafka_spark_dag.kafka_data_stream scheduled__2024-06-21T19:35:45.772550+00:00 [queued]>
[2024-06-21T20:05:47.284+0000] {taskinstance.py:1159} INFO - Dependencies all met for dep_context=requeueable deps ti=<TaskInstance: kafka_spark_dag.kafka_data_stream scheduled__2024-06-21T19:35:45.772550+00:00 [queued]>
[2024-06-21T20:05:47.286+0000] {taskinstance.py:1361} INFO - Starting attempt 1 of 2
[2024-06-21T20:05:47.302+0000] {taskinstance.py:1382} INFO - Executing <Task(PythonOperator): kafka_data_stream> on 2024-06-21 19:35:45.772550+00:00
[2024-06-21T20:05:47.308+0000] {standard_task_runner.py:57} INFO - Started process 63943 to run task
[2024-06-21T20:05:47.312+0000] {standard_task_runner.py:84} INFO - Running: ['***', 'tasks', 'run', 'kafka_spark_dag', 'kafka_data_stream', 'scheduled__2024-06-21T19:35:45.772550+00:00', '--job-id', '1992', '--raw', '--subdir', 'DAGS_FOLDER/dag_kafka_spark.py', '--cfg-path', '/tmp/tmpi4bcylum']
[2024-06-21T20:05:47.316+0000] {standard_task_runner.py:85} INFO - Job 1992: Subtask kafka_data_stream
[2024-06-21T20:05:47.357+0000] {task_command.py:416} INFO - Running <TaskInstance: kafka_spark_dag.kafka_data_stream scheduled__2024-06-21T19:35:45.772550+00:00 [running]> on host 2ad9230613d5
[2024-06-21T20:05:47.377+0000] {standard_task_runner.py:104} ERROR - Failed to execute job 1992 for task kafka_data_stream ((psycopg2.errors.ForeignKeyViolation) update or delete on table "dag_run" violates foreign key constraint "task_instance_dag_run_fkey" on table "task_instance"
DETAIL:  Key (dag_id, run_id)=(kafka_spark_dag, scheduled__2024-06-11T18:54:33.552521+00:00) is still referenced from table "task_instance".

[SQL: UPDATE dag_run SET queued_at=%(queued_at)s, execution_date=%(execution_date)s, start_date=%(start_date)s, end_date=%(end_date)s, state=%(state)s, run_id=%(run_id)s, creating_job_id=%(creating_job_id)s, data_interval_start=%(data_interval_start)s, data_interval_end=%(data_interval_end)s, last_scheduling_decision=%(last_scheduling_decision)s, dag_hash=%(dag_hash)s, updated_at=%(updated_at)s WHERE dag_run.id = %(dag_run_id)s]
[parameters: {'queued_at': datetime.datetime(2024, 6, 21, 20, 5, 45, 934876, tzinfo=Timezone('UTC')), 'execution_date': datetime.datetime(2024, 6, 21, 19, 35, 45, 772550, tzinfo=Timezone('UTC')), 'start_date': datetime.datetime(2024, 6, 21, 20, 5, 45, 975680, tzinfo=Timezone('UTC')), 'end_date': None, 'state': 'running', 'run_id': 'scheduled__2024-06-21T19:35:45.772550+00:00', 'creating_job_id': 246, 'data_interval_start': datetime.datetime(2024, 6, 21, 19, 35, 45, 772550, tzinfo=Timezone('UTC')), 'data_interval_end': datetime.datetime(2024, 6, 21, 20, 5, 45, 772550, tzinfo=Timezone('UTC')), 'last_scheduling_decision': datetime.datetime(2024, 6, 21, 20, 5, 47, 115295, tzinfo=Timezone('UTC')), 'dag_hash': 'dc1c399b9f7320b9244380571f35afa9', 'updated_at': datetime.datetime(2024, 6, 21, 20, 5, 47, 153306, tzinfo=Timezone('UTC')), 'dag_run_id': 169}]
(Background on this error at: https://sqlalche.me/e/14/gkpj); 63943)
[2024-06-21T20:05:47.410+0000] {local_task_job_runner.py:228} INFO - Task exited with return code 1
