[2024-06-22T14:26:30.123+0000] {taskinstance.py:1159} INFO - Dependencies all met for dep_context=non-requeueable deps ti=<TaskInstance: kafka_spark_dag.kafka_data_stream scheduled__2024-06-22T14:21:22.707703+00:00 [queued]>
[2024-06-22T14:26:30.128+0000] {taskinstance.py:1159} INFO - Dependencies all met for dep_context=requeueable deps ti=<TaskInstance: kafka_spark_dag.kafka_data_stream scheduled__2024-06-22T14:21:22.707703+00:00 [queued]>
[2024-06-22T14:26:30.128+0000] {taskinstance.py:1361} INFO - Starting attempt 2 of 2
[2024-06-22T14:26:30.136+0000] {taskinstance.py:1382} INFO - Executing <Task(PythonOperator): kafka_data_stream> on 2024-06-22 14:21:22.707703+00:00
[2024-06-22T14:26:30.139+0000] {standard_task_runner.py:57} INFO - Started process 59957 to run task
[2024-06-22T14:26:30.142+0000] {standard_task_runner.py:84} INFO - Running: ['***', 'tasks', 'run', 'kafka_spark_dag', 'kafka_data_stream', 'scheduled__2024-06-22T14:21:22.707703+00:00', '--job-id', '2027', '--raw', '--subdir', 'DAGS_FOLDER/dag_kafka_spark.py', '--cfg-path', '/tmp/tmpbkn4qw7v']
[2024-06-22T14:26:30.142+0000] {standard_task_runner.py:85} INFO - Job 2027: Subtask kafka_data_stream
[2024-06-22T14:26:30.170+0000] {task_command.py:416} INFO - Running <TaskInstance: kafka_spark_dag.kafka_data_stream scheduled__2024-06-22T14:21:22.707703+00:00 [running]> on host 2ad9230613d5
[2024-06-22T14:26:30.187+0000] {standard_task_runner.py:104} ERROR - Failed to execute job 2027 for task kafka_data_stream ((psycopg2.errors.ForeignKeyViolation) update or delete on table "dag_run" violates foreign key constraint "task_instance_dag_run_fkey" on table "task_instance"
DETAIL:  Key (dag_id, run_id)=(kafka_spark_dag, scheduled__2024-06-12T09:58:45.496202+00:00) is still referenced from table "task_instance".

[SQL: UPDATE dag_run SET queued_at=%(queued_at)s, execution_date=%(execution_date)s, start_date=%(start_date)s, end_date=%(end_date)s, state=%(state)s, run_id=%(run_id)s, creating_job_id=%(creating_job_id)s, data_interval_start=%(data_interval_start)s, data_interval_end=%(data_interval_end)s, last_scheduling_decision=%(last_scheduling_decision)s, dag_hash=%(dag_hash)s, updated_at=%(updated_at)s WHERE dag_run.id = %(dag_run_id)s]
[parameters: {'queued_at': datetime.datetime(2024, 6, 22, 14, 26, 23, 216944, tzinfo=Timezone('UTC')), 'execution_date': datetime.datetime(2024, 6, 22, 14, 21, 22, 707703, tzinfo=Timezone('UTC')), 'start_date': datetime.datetime(2024, 6, 22, 14, 26, 23, 235792, tzinfo=Timezone('UTC')), 'end_date': None, 'state': 'running', 'run_id': 'scheduled__2024-06-22T14:21:22.707703+00:00', 'creating_job_id': 246, 'data_interval_start': datetime.datetime(2024, 6, 22, 14, 21, 22, 707703, tzinfo=Timezone('UTC')), 'data_interval_end': datetime.datetime(2024, 6, 22, 14, 26, 22, 707703, tzinfo=Timezone('UTC')), 'last_scheduling_decision': datetime.datetime(2024, 6, 22, 14, 26, 29, 607325, tzinfo=Timezone('UTC')), 'dag_hash': '256c072f49f1f5042216f4e353867611', 'updated_at': datetime.datetime(2024, 6, 22, 14, 26, 29, 617613, tzinfo=Timezone('UTC')), 'dag_run_id': 232}]
(Background on this error at: https://sqlalche.me/e/14/gkpj); 59957)
[2024-06-22T14:26:30.200+0000] {local_task_job_runner.py:228} INFO - Task exited with return code 1
