[2024-06-19T09:16:43.369+0000] {taskinstance.py:1159} INFO - Dependencies all met for dep_context=non-requeueable deps ti=<TaskInstance: kafka_spark_dag.pyspark_consumer scheduled__2024-06-19T09:11:38.394942+00:00 [queued]>
[2024-06-19T09:16:43.373+0000] {taskinstance.py:1159} INFO - Dependencies all met for dep_context=requeueable deps ti=<TaskInstance: kafka_spark_dag.pyspark_consumer scheduled__2024-06-19T09:11:38.394942+00:00 [queued]>
[2024-06-19T09:16:43.373+0000] {taskinstance.py:1361} INFO - Starting attempt 1 of 2
[2024-06-19T09:16:43.378+0000] {taskinstance.py:1382} INFO - Executing <Task(DockerOperator): pyspark_consumer> on 2024-06-19 09:11:38.394942+00:00
[2024-06-19T09:16:43.382+0000] {standard_task_runner.py:57} INFO - Started process 10222 to run task
[2024-06-19T09:16:43.383+0000] {standard_task_runner.py:84} INFO - Running: ['***', 'tasks', 'run', 'kafka_spark_dag', 'pyspark_consumer', 'scheduled__2024-06-19T09:11:38.394942+00:00', '--job-id', '132', '--raw', '--subdir', 'DAGS_FOLDER/dag_kafka_spark.py', '--cfg-path', '/tmp/tmpais3bpic']
[2024-06-19T09:16:43.384+0000] {standard_task_runner.py:85} INFO - Job 132: Subtask pyspark_consumer
[2024-06-19T09:16:43.406+0000] {task_command.py:416} INFO - Running <TaskInstance: kafka_spark_dag.pyspark_consumer scheduled__2024-06-19T09:11:38.394942+00:00 [running]> on host 2ad9230613d5
[2024-06-19T09:16:43.438+0000] {taskinstance.py:1662} INFO - Exporting env vars: AIRFLOW_CTX_DAG_OWNER='***' AIRFLOW_CTX_DAG_ID='kafka_spark_dag' AIRFLOW_CTX_TASK_ID='pyspark_consumer' AIRFLOW_CTX_EXECUTION_DATE='2024-06-19T09:11:38.394942+00:00' AIRFLOW_CTX_TRY_NUMBER='1' AIRFLOW_CTX_DAG_RUN_ID='scheduled__2024-06-19T09:11:38.394942+00:00'
[2024-06-19T09:16:43.525+0000] {docker.py:343} INFO - Starting docker container from image rappel-conso/spark:latest
[2024-06-19T09:16:43.577+0000] {docker.py:351} WARNING - Using remote engine or docker-in-docker and mounting temporary volume from host is not supported. Falling back to `mount_tmp_dir=False` mode. You can set `mount_tmp_dir` parameter to False to disable mounting and remove the warning
[2024-06-19T09:16:43.915+0000] {docker.py:413} INFO - [38;5;6mspark [38;5;5m09:16:43.91 [0m[38;5;2mINFO [0m ==>
[2024-06-19T09:16:43.916+0000] {docker.py:413} INFO - [38;5;6mspark [38;5;5m09:16:43.91 [0m[38;5;2mINFO [0m ==> [1mWelcome to the Bitnami spark container[0m
[2024-06-19T09:16:43.916+0000] {docker.py:413} INFO - [38;5;6mspark [38;5;5m09:16:43.91 [0m[38;5;2mINFO [0m ==> Subscribe to project updates by watching [1mhttps://github.com/bitnami/containers[0m
[2024-06-19T09:16:43.917+0000] {docker.py:413} INFO - [38;5;6mspark [38;5;5m09:16:43.91 [0m[38;5;2mINFO [0m ==> Submit issues and feature requests at [1mhttps://github.com/bitnami/containers/issues[0m
[2024-06-19T09:16:43.917+0000] {docker.py:413} INFO - [38;5;6mspark [38;5;5m09:16:43.91 [0m[38;5;2mINFO [0m ==>
[2024-06-19T09:16:43.927+0000] {docker.py:413} INFO - 
[2024-06-19T09:16:45.315+0000] {docker.py:413} INFO - :: loading settings :: url = jar:file:/opt/bitnami/spark/jars/ivy-2.5.1.jar!/org/apache/ivy/core/settings/ivysettings.xml
[2024-06-19T09:16:45.350+0000] {docker.py:413} INFO - Ivy Default Cache set to: /opt/bitnami/spark/.ivy2/cache
The jars for the packages stored in: /opt/bitnami/spark/.ivy2/jars
[2024-06-19T09:16:45.353+0000] {docker.py:413} INFO - org.postgresql#postgresql added as a dependency
org.apache.spark#spark-sql-kafka-0-10_2.12 added as a dependency
[2024-06-19T09:16:45.353+0000] {docker.py:413} INFO - :: resolving dependencies :: org.apache.spark#spark-submit-parent-9755fd79-c7c4-4d6f-81d5-9c82e62d33c7;1.0
	confs: [default]
[2024-06-19T09:16:47.147+0000] {docker.py:413} INFO - found org.postgresql#postgresql;42.5.4 in central
[2024-06-19T09:16:47.620+0000] {docker.py:413} INFO - found org.checkerframework#checker-qual;3.5.0 in central
[2024-06-19T09:16:52.698+0000] {docker.py:413} INFO - found org.apache.spark#spark-sql-kafka-0-10_2.12;3.5.0 in central
[2024-06-19T09:16:53.394+0000] {docker.py:413} INFO - found org.apache.spark#spark-token-provider-kafka-0-10_2.12;3.5.0 in central
[2024-06-19T09:16:53.984+0000] {docker.py:413} INFO - found org.apache.kafka#kafka-clients;3.4.1 in central
[2024-06-19T09:16:54.593+0000] {docker.py:413} INFO - found org.lz4#lz4-java;1.8.0 in central
[2024-06-19T09:16:55.112+0000] {docker.py:413} INFO - found org.xerial.snappy#snappy-java;1.1.10.3 in central
[2024-06-19T09:16:57.502+0000] {docker.py:413} INFO - found org.slf4j#slf4j-api;2.0.7 in central
[2024-06-19T09:17:01.908+0000] {docker.py:413} INFO - found org.apache.hadoop#hadoop-client-runtime;3.3.4 in central
[2024-06-19T09:17:02.449+0000] {docker.py:413} INFO - found org.apache.hadoop#hadoop-client-api;3.3.4 in central
[2024-06-19T09:37:29.481+0000] {local_task_job_runner.py:274} WARNING - Recorded pid 10889 does not match the current pid 10222
[2024-06-19T09:37:29.492+0000] {process_utils.py:131} INFO - Sending 15 to group 10222. PIDs of all processes in the group: [10222]
[2024-06-19T09:37:29.493+0000] {process_utils.py:86} INFO - Sending the signal 15 to group 10222
[2024-06-19T09:37:29.498+0000] {taskinstance.py:1632} ERROR - Received SIGTERM. Terminating subprocesses.
[2024-06-19T09:37:29.506+0000] {docker.py:505} INFO - Stopping docker container
[2024-06-19T09:37:30.095+0000] {taskinstance.py:1937} ERROR - Task failed with exception
Traceback (most recent call last):
  File "/home/airflow/.local/lib/python3.8/site-packages/docker/api/client.py", line 268, in _raise_for_status
    response.raise_for_status()
  File "/home/airflow/.local/lib/python3.8/site-packages/requests/models.py", line 1021, in raise_for_status
    raise HTTPError(http_error_msg, response=self)
requests.exceptions.HTTPError: 400 Client Error: Bad Request for url: http://docker-proxy:2375/v1.44/containers/create

The above exception was the direct cause of the following exception:

Traceback (most recent call last):
  File "/home/airflow/.local/lib/python3.8/site-packages/airflow/providers/docker/operators/docker.py", line 348, in _run_image
    return self._run_image_with_mounts([*self.mounts, tmp_mount], add_tmp_variable=True)
  File "/home/airflow/.local/lib/python3.8/site-packages/airflow/providers/docker/operators/docker.py", line 375, in _run_image_with_mounts
    self.container = self.cli.create_container(
  File "/home/airflow/.local/lib/python3.8/site-packages/docker/api/container.py", line 431, in create_container
    return self.create_container_from_config(config, name, platform)
  File "/home/airflow/.local/lib/python3.8/site-packages/docker/api/container.py", line 448, in create_container_from_config
    return self._result(res, True)
  File "/home/airflow/.local/lib/python3.8/site-packages/docker/api/client.py", line 274, in _result
    self._raise_for_status(response)
  File "/home/airflow/.local/lib/python3.8/site-packages/docker/api/client.py", line 270, in _raise_for_status
    raise create_api_error_from_http_exception(e) from e
  File "/home/airflow/.local/lib/python3.8/site-packages/docker/errors.py", line 39, in create_api_error_from_http_exception
    raise cls(e, response=response, explanation=explanation) from e
docker.errors.APIError: 400 Client Error for http://docker-proxy:2375/v1.44/containers/create: Bad Request ("invalid mount config for type "bind": bind source path does not exist: /host_mnt/private/tmp/airflowtmpvk_usftg")

During handling of the above exception, another exception occurred:

Traceback (most recent call last):
  File "/home/airflow/.local/lib/python3.8/site-packages/airflow/providers/docker/operators/docker.py", line 486, in execute
    return self._run_image()
  File "/home/airflow/.local/lib/python3.8/site-packages/airflow/providers/docker/operators/docker.py", line 357, in _run_image
    return self._run_image_with_mounts(self.mounts, add_tmp_variable=False)
  File "/home/airflow/.local/lib/python3.8/site-packages/airflow/providers/docker/operators/docker.py", line 410, in _run_image_with_mounts
    for log_chunk in logstream:
  File "/home/airflow/.local/lib/python3.8/site-packages/docker/types/daemon.py", line 29, in __next__
    return next(self._stream)
  File "/home/airflow/.local/lib/python3.8/site-packages/docker/api/client.py", line 422, in <genexpr>
    gen = (data for (_, data) in gen)
  File "/home/airflow/.local/lib/python3.8/site-packages/docker/utils/socket.py", line 112, in frames_iter_no_tty
    (stream, n) = next_frame_header(socket)
  File "/home/airflow/.local/lib/python3.8/site-packages/docker/utils/socket.py", line 84, in next_frame_header
    data = read_exactly(socket, 8)
  File "/home/airflow/.local/lib/python3.8/site-packages/docker/utils/socket.py", line 69, in read_exactly
    next_data = read(socket, n - len(data))
  File "/home/airflow/.local/lib/python3.8/site-packages/docker/utils/socket.py", line 40, in read
    poll.poll()
  File "/home/airflow/.local/lib/python3.8/site-packages/airflow/models/taskinstance.py", line 1634, in signal_handler
    raise AirflowException("Task received SIGTERM signal")
airflow.exceptions.AirflowException: Task received SIGTERM signal
[2024-06-19T09:37:30.106+0000] {taskinstance.py:1400} INFO - Marking task as FAILED. dag_id=kafka_spark_dag, task_id=pyspark_consumer, execution_date=20240619T091138, start_date=20240619T093726, end_date=20240619T093730
[2024-06-19T09:37:30.120+0000] {standard_task_runner.py:104} ERROR - Failed to execute job 132 for task pyspark_consumer (Task received SIGTERM signal; 10222)
[2024-06-19T09:37:30.165+0000] {process_utils.py:79} INFO - Process psutil.Process(pid=10222, status='terminated', exitcode=1, started='09:16:42') (10222) terminated with exit code 1
