[2024-06-20T10:32:35.577+0000] {taskinstance.py:1159} INFO - Dependencies all met for dep_context=non-requeueable deps ti=<TaskInstance: kafka_spark_dag.kafka_data_stream scheduled__2024-06-19T15:25:20.814520+00:00 [queued]>
[2024-06-20T10:32:35.581+0000] {taskinstance.py:1159} INFO - Dependencies all met for dep_context=requeueable deps ti=<TaskInstance: kafka_spark_dag.kafka_data_stream scheduled__2024-06-19T15:25:20.814520+00:00 [queued]>
[2024-06-20T10:32:35.581+0000] {taskinstance.py:1361} INFO - Starting attempt 2 of 2
[2024-06-20T10:32:35.587+0000] {taskinstance.py:1382} INFO - Executing <Task(PythonOperator): kafka_data_stream> on 2024-06-19 15:25:20.814520+00:00
[2024-06-20T10:32:35.594+0000] {standard_task_runner.py:57} INFO - Started process 422 to run task
[2024-06-20T10:32:35.604+0000] {standard_task_runner.py:84} INFO - Running: ['***', 'tasks', 'run', 'kafka_spark_dag', 'kafka_data_stream', 'scheduled__2024-06-19T15:25:20.814520+00:00', '--job-id', '194', '--raw', '--subdir', 'DAGS_FOLDER/dag_kafka_spark.py', '--cfg-path', '/tmp/tmpvv5gcfvq']
[2024-06-20T10:32:35.605+0000] {standard_task_runner.py:85} INFO - Job 194: Subtask kafka_data_stream
[2024-06-20T10:32:35.630+0000] {task_command.py:416} INFO - Running <TaskInstance: kafka_spark_dag.kafka_data_stream scheduled__2024-06-19T15:25:20.814520+00:00 [running]> on host 2ad9230613d5
[2024-06-20T10:32:35.645+0000] {standard_task_runner.py:104} ERROR - Failed to execute job 194 for task kafka_data_stream ((psycopg2.errors.ForeignKeyViolation) update or delete on table "dag_run" violates foreign key constraint "task_instance_dag_run_fkey" on table "task_instance"
DETAIL:  Key (dag_id, run_id)=(kafka_spark_dag, scheduled__2024-06-11T08:20:14.936687+00:00) is still referenced from table "task_instance".

[SQL: UPDATE dag_run SET queued_at=%(queued_at)s, execution_date=%(execution_date)s, start_date=%(start_date)s, end_date=%(end_date)s, state=%(state)s, run_id=%(run_id)s, creating_job_id=%(creating_job_id)s, data_interval_start=%(data_interval_start)s, data_interval_end=%(data_interval_end)s, last_scheduling_decision=%(last_scheduling_decision)s, dag_hash=%(dag_hash)s, updated_at=%(updated_at)s WHERE dag_run.id = %(dag_run_id)s]
[parameters: {'queued_at': datetime.datetime(2024, 6, 20, 10, 32, 26, 849652, tzinfo=Timezone('UTC')), 'execution_date': datetime.datetime(2024, 6, 19, 15, 25, 20, 814520, tzinfo=Timezone('UTC')), 'start_date': datetime.datetime(2024, 6, 20, 10, 32, 26, 932650, tzinfo=Timezone('UTC')), 'end_date': None, 'state': 'running', 'run_id': 'scheduled__2024-06-19T15:25:20.814520+00:00', 'creating_job_id': 188, 'data_interval_start': datetime.datetime(2024, 6, 19, 15, 25, 20, 814520, tzinfo=Timezone('UTC')), 'data_interval_end': datetime.datetime(2024, 6, 19, 15, 55, 20, 814520, tzinfo=Timezone('UTC')), 'last_scheduling_decision': datetime.datetime(2024, 6, 20, 10, 32, 35, 51955, tzinfo=Timezone('UTC')), 'dag_hash': '0d1c2ead48b41eba1d0c0d1fe3275673', 'updated_at': datetime.datetime(2024, 6, 20, 10, 32, 35, 56353, tzinfo=Timezone('UTC')), 'dag_run_id': 68}]
(Background on this error at: https://sqlalche.me/e/14/gkpj); 422)
[2024-06-20T10:32:35.661+0000] {local_task_job_runner.py:228} INFO - Task exited with return code 1
