[2024-06-21T12:19:36.440+0000] {taskinstance.py:1159} INFO - Dependencies all met for dep_context=non-requeueable deps ti=<TaskInstance: kafka_spark_dag.pyspark_consumer scheduled__2024-06-20T15:53:46.003430+00:00 [queued]>
[2024-06-21T12:19:36.444+0000] {taskinstance.py:1159} INFO - Dependencies all met for dep_context=requeueable deps ti=<TaskInstance: kafka_spark_dag.pyspark_consumer scheduled__2024-06-20T15:53:46.003430+00:00 [queued]>
[2024-06-21T12:19:36.445+0000] {taskinstance.py:1361} INFO - Starting attempt 2 of 2
[2024-06-21T12:19:36.453+0000] {taskinstance.py:1382} INFO - Executing <Task(DockerOperator): pyspark_consumer> on 2024-06-20 15:53:46.003430+00:00
[2024-06-21T12:19:36.455+0000] {standard_task_runner.py:57} INFO - Started process 28968 to run task
[2024-06-21T12:19:36.457+0000] {standard_task_runner.py:84} INFO - Running: ['***', 'tasks', 'run', 'kafka_spark_dag', 'pyspark_consumer', 'scheduled__2024-06-20T15:53:46.003430+00:00', '--job-id', '1960', '--raw', '--subdir', 'DAGS_FOLDER/dag_kafka_spark.py', '--cfg-path', '/tmp/tmprhjk_nfm']
[2024-06-21T12:19:36.458+0000] {standard_task_runner.py:85} INFO - Job 1960: Subtask pyspark_consumer
[2024-06-21T12:19:36.480+0000] {task_command.py:416} INFO - Running <TaskInstance: kafka_spark_dag.pyspark_consumer scheduled__2024-06-20T15:53:46.003430+00:00 [running]> on host 2ad9230613d5
[2024-06-21T12:19:36.493+0000] {standard_task_runner.py:104} ERROR - Failed to execute job 1960 for task pyspark_consumer ((psycopg2.errors.ForeignKeyViolation) update or delete on table "dag_run" violates foreign key constraint "task_instance_dag_run_fkey" on table "task_instance"
DETAIL:  Key (dag_id, run_id)=(kafka_spark_dag, scheduled__2024-06-11T11:01:34.381691+00:00) is still referenced from table "task_instance".

[SQL: UPDATE dag_run SET queued_at=%(queued_at)s, execution_date=%(execution_date)s, start_date=%(start_date)s, end_date=%(end_date)s, state=%(state)s, run_id=%(run_id)s, creating_job_id=%(creating_job_id)s, data_interval_start=%(data_interval_start)s, data_interval_end=%(data_interval_end)s, last_scheduling_decision=%(last_scheduling_decision)s, dag_hash=%(dag_hash)s, updated_at=%(updated_at)s WHERE dag_run.id = %(dag_run_id)s]
[parameters: {'queued_at': datetime.datetime(2024, 6, 20, 16, 23, 46, 791033, tzinfo=Timezone('UTC')), 'execution_date': datetime.datetime(2024, 6, 20, 15, 53, 46, 3430, tzinfo=Timezone('UTC')), 'start_date': datetime.datetime(2024, 6, 20, 16, 23, 46, 808918, tzinfo=Timezone('UTC')), 'end_date': None, 'state': 'running', 'run_id': 'scheduled__2024-06-20T15:53:46.003430+00:00', 'creating_job_id': 229, 'data_interval_start': datetime.datetime(2024, 6, 20, 15, 53, 46, 3430, tzinfo=Timezone('UTC')), 'data_interval_end': datetime.datetime(2024, 6, 20, 16, 23, 46, 3430, tzinfo=Timezone('UTC')), 'last_scheduling_decision': datetime.datetime(2024, 6, 21, 12, 19, 35, 545809, tzinfo=Timezone('UTC')), 'dag_hash': '4443a14dd9ff3f42a8f1530faa67fc56', 'updated_at': datetime.datetime(2024, 6, 21, 12, 19, 35, 557667, tzinfo=Timezone('UTC')), 'dag_run_id': 101}]
(Background on this error at: https://sqlalche.me/e/14/gkpj); 28968)
[2024-06-21T12:19:36.516+0000] {local_task_job_runner.py:228} INFO - Task exited with return code 1
