[2024-06-21T21:53:51.668+0000] {taskinstance.py:1159} INFO - Dependencies all met for dep_context=non-requeueable deps ti=<TaskInstance: kafka_spark_dag.kafka_data_stream scheduled__2024-06-21T21:48:43.796161+00:00 [queued]>
[2024-06-21T21:53:51.674+0000] {taskinstance.py:1159} INFO - Dependencies all met for dep_context=requeueable deps ti=<TaskInstance: kafka_spark_dag.kafka_data_stream scheduled__2024-06-21T21:48:43.796161+00:00 [queued]>
[2024-06-21T21:53:51.674+0000] {taskinstance.py:1361} INFO - Starting attempt 2 of 2
[2024-06-21T21:53:51.682+0000] {taskinstance.py:1382} INFO - Executing <Task(PythonOperator): kafka_data_stream> on 2024-06-21 21:48:43.796161+00:00
[2024-06-21T21:53:51.686+0000] {standard_task_runner.py:57} INFO - Started process 97942 to run task
[2024-06-21T21:53:51.691+0000] {standard_task_runner.py:84} INFO - Running: ['***', 'tasks', 'run', 'kafka_spark_dag', 'kafka_data_stream', 'scheduled__2024-06-21T21:48:43.796161+00:00', '--job-id', '291', '--raw', '--subdir', 'DAGS_FOLDER/dag_kafka_spark.py', '--cfg-path', '/tmp/tmpfznufcj2']
[2024-06-21T21:53:51.692+0000] {standard_task_runner.py:85} INFO - Job 291: Subtask kafka_data_stream
[2024-06-21T21:53:52.078+0000] {task_command.py:416} INFO - Running <TaskInstance: kafka_spark_dag.kafka_data_stream scheduled__2024-06-21T21:48:43.796161+00:00 [running]> on host 2ad9230613d5
[2024-06-21T21:53:52.132+0000] {standard_task_runner.py:104} ERROR - Failed to execute job 291 for task kafka_data_stream ((psycopg2.errors.ForeignKeyViolation) update or delete on table "dag_run" violates foreign key constraint "task_instance_dag_run_fkey" on table "task_instance"
DETAIL:  Key (dag_id, run_id)=(kafka_spark_dag, scheduled__2024-06-12T04:11:43.043858+00:00) is still referenced from table "task_instance".

[SQL: UPDATE dag_run SET queued_at=%(queued_at)s, execution_date=%(execution_date)s, start_date=%(start_date)s, end_date=%(end_date)s, state=%(state)s, run_id=%(run_id)s, creating_job_id=%(creating_job_id)s, data_interval_start=%(data_interval_start)s, data_interval_end=%(data_interval_end)s, last_scheduling_decision=%(last_scheduling_decision)s, dag_hash=%(dag_hash)s, updated_at=%(updated_at)s WHERE dag_run.id = %(dag_run_id)s]
[parameters: {'queued_at': datetime.datetime(2024, 6, 21, 21, 53, 44, 106844, tzinfo=Timezone('UTC')), 'execution_date': datetime.datetime(2024, 6, 21, 21, 48, 43, 796161, tzinfo=Timezone('UTC')), 'start_date': datetime.datetime(2024, 6, 21, 21, 53, 44, 119073, tzinfo=Timezone('UTC')), 'end_date': None, 'state': 'running', 'run_id': 'scheduled__2024-06-21T21:48:43.796161+00:00', 'creating_job_id': 246, 'data_interval_start': datetime.datetime(2024, 6, 21, 21, 48, 43, 796161, tzinfo=Timezone('UTC')), 'data_interval_end': datetime.datetime(2024, 6, 21, 21, 53, 43, 796161, tzinfo=Timezone('UTC')), 'last_scheduling_decision': datetime.datetime(2024, 6, 21, 21, 53, 51, 228567, tzinfo=Timezone('UTC')), 'dag_hash': 'd6cf1d40f8c522e4a71d4d21c39300ec', 'updated_at': datetime.datetime(2024, 6, 21, 21, 53, 51, 247732, tzinfo=Timezone('UTC')), 'dag_run_id': 187}]
(Background on this error at: https://sqlalche.me/e/14/gkpj); 97942)
[2024-06-21T21:53:52.145+0000] {local_task_job_runner.py:228} INFO - Task exited with return code 1
