[2024-06-21T13:39:02.815+0000] {taskinstance.py:1159} INFO - Dependencies all met for dep_context=non-requeueable deps ti=<TaskInstance: kafka_spark_dag.kafka_data_stream scheduled__2024-06-21T13:34:01.493957+00:00 [queued]>
[2024-06-21T13:39:02.818+0000] {taskinstance.py:1159} INFO - Dependencies all met for dep_context=requeueable deps ti=<TaskInstance: kafka_spark_dag.kafka_data_stream scheduled__2024-06-21T13:34:01.493957+00:00 [queued]>
[2024-06-21T13:39:02.819+0000] {taskinstance.py:1361} INFO - Starting attempt 1 of 2
[2024-06-21T13:39:02.825+0000] {taskinstance.py:1382} INFO - Executing <Task(PythonOperator): kafka_data_stream> on 2024-06-21 13:34:01.493957+00:00
[2024-06-21T13:39:02.829+0000] {standard_task_runner.py:57} INFO - Started process 67180 to run task
[2024-06-21T13:39:02.832+0000] {standard_task_runner.py:84} INFO - Running: ['***', 'tasks', 'run', 'kafka_spark_dag', 'kafka_data_stream', 'scheduled__2024-06-21T13:34:01.493957+00:00', '--job-id', '261', '--raw', '--subdir', 'DAGS_FOLDER/dag_kafka_spark.py', '--cfg-path', '/tmp/tmpqzyxfy5q']
[2024-06-21T13:39:02.832+0000] {standard_task_runner.py:85} INFO - Job 261: Subtask kafka_data_stream
[2024-06-21T13:39:02.858+0000] {task_command.py:416} INFO - Running <TaskInstance: kafka_spark_dag.kafka_data_stream scheduled__2024-06-21T13:34:01.493957+00:00 [running]> on host 2ad9230613d5
[2024-06-21T13:39:02.872+0000] {standard_task_runner.py:104} ERROR - Failed to execute job 261 for task kafka_data_stream ((psycopg2.errors.ForeignKeyViolation) update or delete on table "dag_run" violates foreign key constraint "task_instance_dag_run_fkey" on table "task_instance"
DETAIL:  Key (dag_id, run_id)=(kafka_spark_dag, scheduled__2024-06-11T12:51:34.589569+00:00) is still referenced from table "task_instance".

[SQL: UPDATE dag_run SET queued_at=%(queued_at)s, execution_date=%(execution_date)s, start_date=%(start_date)s, end_date=%(end_date)s, state=%(state)s, run_id=%(run_id)s, creating_job_id=%(creating_job_id)s, data_interval_start=%(data_interval_start)s, data_interval_end=%(data_interval_end)s, last_scheduling_decision=%(last_scheduling_decision)s, dag_hash=%(dag_hash)s, updated_at=%(updated_at)s WHERE dag_run.id = %(dag_run_id)s]
[parameters: {'queued_at': datetime.datetime(2024, 6, 21, 13, 39, 2, 156099, tzinfo=Timezone('UTC')), 'execution_date': datetime.datetime(2024, 6, 21, 13, 34, 1, 493957, tzinfo=Timezone('UTC')), 'start_date': datetime.datetime(2024, 6, 21, 13, 39, 2, 168932, tzinfo=Timezone('UTC')), 'end_date': None, 'state': 'running', 'run_id': 'scheduled__2024-06-21T13:34:01.493957+00:00', 'creating_job_id': 246, 'data_interval_start': datetime.datetime(2024, 6, 21, 13, 34, 1, 493957, tzinfo=Timezone('UTC')), 'data_interval_end': datetime.datetime(2024, 6, 21, 13, 39, 1, 493957, tzinfo=Timezone('UTC')), 'last_scheduling_decision': datetime.datetime(2024, 6, 21, 13, 39, 2, 410036, tzinfo=Timezone('UTC')), 'dag_hash': 'b578e155c24a7f67d71d94e93249c633', 'updated_at': datetime.datetime(2024, 6, 21, 13, 39, 2, 416102, tzinfo=Timezone('UTC')), 'dag_run_id': 123}]
(Background on this error at: https://sqlalche.me/e/14/gkpj); 67180)
[2024-06-21T13:39:02.889+0000] {local_task_job_runner.py:228} INFO - Task exited with return code 1
