[2024-06-21T21:32:57.801+0000] {taskinstance.py:1159} INFO - Dependencies all met for dep_context=non-requeueable deps ti=<TaskInstance: kafka_spark_dag.kafka_data_stream scheduled__2024-06-21T21:27:49.682219+00:00 [queued]>
[2024-06-21T21:32:57.805+0000] {taskinstance.py:1159} INFO - Dependencies all met for dep_context=requeueable deps ti=<TaskInstance: kafka_spark_dag.kafka_data_stream scheduled__2024-06-21T21:27:49.682219+00:00 [queued]>
[2024-06-21T21:32:57.806+0000] {taskinstance.py:1361} INFO - Starting attempt 2 of 2
[2024-06-21T21:32:57.813+0000] {taskinstance.py:1382} INFO - Executing <Task(PythonOperator): kafka_data_stream> on 2024-06-21 21:27:49.682219+00:00
[2024-06-21T21:32:57.820+0000] {standard_task_runner.py:57} INFO - Started process 87986 to run task
[2024-06-21T21:32:57.823+0000] {standard_task_runner.py:84} INFO - Running: ['***', 'tasks', 'run', 'kafka_spark_dag', 'kafka_data_stream', 'scheduled__2024-06-21T21:27:49.682219+00:00', '--job-id', '2002', '--raw', '--subdir', 'DAGS_FOLDER/dag_kafka_spark.py', '--cfg-path', '/tmp/tmprc0a4w81']
[2024-06-21T21:32:57.824+0000] {standard_task_runner.py:85} INFO - Job 2002: Subtask kafka_data_stream
[2024-06-21T21:32:57.855+0000] {task_command.py:416} INFO - Running <TaskInstance: kafka_spark_dag.kafka_data_stream scheduled__2024-06-21T21:27:49.682219+00:00 [running]> on host 2ad9230613d5
[2024-06-21T21:32:57.874+0000] {standard_task_runner.py:104} ERROR - Failed to execute job 2002 for task kafka_data_stream ((psycopg2.errors.ForeignKeyViolation) update or delete on table "dag_run" violates foreign key constraint "task_instance_dag_run_fkey" on table "task_instance"
DETAIL:  Key (dag_id, run_id)=(kafka_spark_dag, scheduled__2024-06-12T01:50:04.786018+00:00) is still referenced from table "task_instance".

[SQL: UPDATE dag_run SET queued_at=%(queued_at)s, execution_date=%(execution_date)s, start_date=%(start_date)s, end_date=%(end_date)s, state=%(state)s, run_id=%(run_id)s, creating_job_id=%(creating_job_id)s, data_interval_start=%(data_interval_start)s, data_interval_end=%(data_interval_end)s, last_scheduling_decision=%(last_scheduling_decision)s, dag_hash=%(dag_hash)s, updated_at=%(updated_at)s WHERE dag_run.id = %(dag_run_id)s]
[parameters: {'queued_at': datetime.datetime(2024, 6, 21, 21, 32, 49, 846078, tzinfo=Timezone('UTC')), 'execution_date': datetime.datetime(2024, 6, 21, 21, 27, 49, 682219, tzinfo=Timezone('UTC')), 'start_date': datetime.datetime(2024, 6, 21, 21, 32, 49, 853345, tzinfo=Timezone('UTC')), 'end_date': None, 'state': 'running', 'run_id': 'scheduled__2024-06-21T21:27:49.682219+00:00', 'creating_job_id': 246, 'data_interval_start': datetime.datetime(2024, 6, 21, 21, 27, 49, 682219, tzinfo=Timezone('UTC')), 'data_interval_end': datetime.datetime(2024, 6, 21, 21, 32, 49, 682219, tzinfo=Timezone('UTC')), 'last_scheduling_decision': datetime.datetime(2024, 6, 21, 21, 32, 57, 29997, tzinfo=Timezone('UTC')), 'dag_hash': '5559dd706c171231982d4e1b5a2ae97a', 'updated_at': datetime.datetime(2024, 6, 21, 21, 32, 57, 38868, tzinfo=Timezone('UTC')), 'dag_run_id': 182}]
(Background on this error at: https://sqlalche.me/e/14/gkpj); 87986)
[2024-06-21T21:32:57.879+0000] {local_task_job_runner.py:228} INFO - Task exited with return code 1
[2024-06-21T21:32:57.895+0000] {taskinstance.py:2778} INFO - 0 downstream tasks scheduled from follow-on schedule check
