[2024-06-20T10:32:28.991+0000] {taskinstance.py:1159} INFO - Dependencies all met for dep_context=non-requeueable deps ti=<TaskInstance: kafka_spark_dag.pyspark_consumer manual__2024-06-19T15:28:44.875877+00:00 [queued]>
[2024-06-20T10:32:29.006+0000] {taskinstance.py:1159} INFO - Dependencies all met for dep_context=requeueable deps ti=<TaskInstance: kafka_spark_dag.pyspark_consumer manual__2024-06-19T15:28:44.875877+00:00 [queued]>
[2024-06-20T10:32:29.008+0000] {taskinstance.py:1361} INFO - Starting attempt 2 of 2
[2024-06-20T10:32:29.022+0000] {taskinstance.py:1382} INFO - Executing <Task(DockerOperator): pyspark_consumer> on 2024-06-19 15:28:44.875877+00:00
[2024-06-20T10:32:29.027+0000] {standard_task_runner.py:57} INFO - Started process 240 to run task
[2024-06-20T10:32:29.030+0000] {standard_task_runner.py:84} INFO - Running: ['***', 'tasks', 'run', 'kafka_spark_dag', 'pyspark_consumer', 'manual__2024-06-19T15:28:44.875877+00:00', '--job-id', '191', '--raw', '--subdir', 'DAGS_FOLDER/dag_kafka_spark.py', '--cfg-path', '/tmp/tmpj22_xkeo']
[2024-06-20T10:32:29.032+0000] {standard_task_runner.py:85} INFO - Job 191: Subtask pyspark_consumer
[2024-06-20T10:32:29.086+0000] {task_command.py:416} INFO - Running <TaskInstance: kafka_spark_dag.pyspark_consumer manual__2024-06-19T15:28:44.875877+00:00 [running]> on host 2ad9230613d5
[2024-06-20T10:32:29.109+0000] {standard_task_runner.py:104} ERROR - Failed to execute job 191 for task pyspark_consumer ((psycopg2.errors.ForeignKeyViolation) update or delete on table "dag_run" violates foreign key constraint "task_instance_dag_run_fkey" on table "task_instance"
DETAIL:  Key (dag_id, run_id)=(kafka_spark_dag, scheduled__2024-06-11T07:18:24.349272+00:00) is still referenced from table "task_instance".

[SQL: UPDATE dag_run SET queued_at=%(queued_at)s, execution_date=%(execution_date)s, start_date=%(start_date)s, end_date=%(end_date)s, state=%(state)s, run_id=%(run_id)s, creating_job_id=%(creating_job_id)s, external_trigger=%(external_trigger)s, run_type=%(run_type)s, data_interval_start=%(data_interval_start)s, data_interval_end=%(data_interval_end)s, last_scheduling_decision=%(last_scheduling_decision)s, dag_hash=%(dag_hash)s, updated_at=%(updated_at)s WHERE dag_run.id = %(dag_run_id)s]
[parameters: {'queued_at': datetime.datetime(2024, 6, 19, 15, 28, 44, 902071, tzinfo=Timezone('UTC')), 'execution_date': datetime.datetime(2024, 6, 19, 15, 28, 44, 875877, tzinfo=Timezone('UTC')), 'start_date': datetime.datetime(2024, 6, 19, 15, 28, 45, 449297, tzinfo=Timezone('UTC')), 'end_date': None, 'state': 'running', 'run_id': 'manual__2024-06-19T15:28:44.875877+00:00', 'creating_job_id': None, 'external_trigger': True, 'run_type': 'manual', 'data_interval_start': datetime.datetime(2024, 6, 19, 14, 58, 44, 875877, tzinfo=Timezone('UTC')), 'data_interval_end': datetime.datetime(2024, 6, 19, 15, 28, 44, 875877, tzinfo=Timezone('UTC')), 'last_scheduling_decision': datetime.datetime(2024, 6, 20, 10, 32, 28, 367362, tzinfo=Timezone('UTC')), 'dag_hash': '0d1c2ead48b41eba1d0c0d1fe3275673', 'updated_at': datetime.datetime(2024, 6, 20, 10, 32, 28, 369438, tzinfo=Timezone('UTC')), 'dag_run_id': 67}]
(Background on this error at: https://sqlalche.me/e/14/gkpj); 240)
[2024-06-20T10:32:29.136+0000] {local_task_job_runner.py:228} INFO - Task exited with return code 1
[2024-06-20T10:32:29.159+0000] {taskinstance.py:2778} INFO - 0 downstream tasks scheduled from follow-on schedule check
