[2024-06-20T10:43:39.515+0000] {taskinstance.py:1159} INFO - Dependencies all met for dep_context=non-requeueable deps ti=<TaskInstance: kafka_spark_dag.kafka_data_stream scheduled__2024-06-20T10:38:32.466685+00:00 [queued]>
[2024-06-20T10:43:39.528+0000] {taskinstance.py:1159} INFO - Dependencies all met for dep_context=requeueable deps ti=<TaskInstance: kafka_spark_dag.kafka_data_stream scheduled__2024-06-20T10:38:32.466685+00:00 [queued]>
[2024-06-20T10:43:39.530+0000] {taskinstance.py:1361} INFO - Starting attempt 2 of 2
[2024-06-20T10:43:39.549+0000] {taskinstance.py:1382} INFO - Executing <Task(PythonOperator): kafka_data_stream> on 2024-06-20 10:38:32.466685+00:00
[2024-06-20T10:43:39.553+0000] {standard_task_runner.py:57} INFO - Started process 5594 to run task
[2024-06-20T10:43:39.556+0000] {standard_task_runner.py:84} INFO - Running: ['***', 'tasks', 'run', 'kafka_spark_dag', 'kafka_data_stream', 'scheduled__2024-06-20T10:38:32.466685+00:00', '--job-id', '1943', '--raw', '--subdir', 'DAGS_FOLDER/dag_kafka_spark.py', '--cfg-path', '/tmp/tmpvsiiijiq']
[2024-06-20T10:43:39.557+0000] {standard_task_runner.py:85} INFO - Job 1943: Subtask kafka_data_stream
[2024-06-20T10:43:39.594+0000] {task_command.py:416} INFO - Running <TaskInstance: kafka_spark_dag.kafka_data_stream scheduled__2024-06-20T10:38:32.466685+00:00 [running]> on host 2ad9230613d5
[2024-06-20T10:43:39.612+0000] {standard_task_runner.py:104} ERROR - Failed to execute job 1943 for task kafka_data_stream ((psycopg2.errors.ForeignKeyViolation) update or delete on table "dag_run" violates foreign key constraint "task_instance_dag_run_fkey" on table "task_instance"
DETAIL:  Key (dag_id, run_id)=(kafka_spark_dag, scheduled__2024-06-11T08:41:34.381691+00:00) is still referenced from table "task_instance".

[SQL: UPDATE dag_run SET queued_at=%(queued_at)s, execution_date=%(execution_date)s, start_date=%(start_date)s, end_date=%(end_date)s, state=%(state)s, run_id=%(run_id)s, creating_job_id=%(creating_job_id)s, data_interval_start=%(data_interval_start)s, data_interval_end=%(data_interval_end)s, last_scheduling_decision=%(last_scheduling_decision)s, dag_hash=%(dag_hash)s, updated_at=%(updated_at)s WHERE dag_run.id = %(dag_run_id)s]
[parameters: {'queued_at': datetime.datetime(2024, 6, 20, 10, 43, 32, 922220, tzinfo=Timezone('UTC')), 'execution_date': datetime.datetime(2024, 6, 20, 10, 38, 32, 466685, tzinfo=Timezone('UTC')), 'start_date': datetime.datetime(2024, 6, 20, 10, 43, 32, 936597, tzinfo=Timezone('UTC')), 'end_date': None, 'state': 'running', 'run_id': 'scheduled__2024-06-20T10:38:32.466685+00:00', 'creating_job_id': 188, 'data_interval_start': datetime.datetime(2024, 6, 20, 10, 38, 32, 466685, tzinfo=Timezone('UTC')), 'data_interval_end': datetime.datetime(2024, 6, 20, 10, 43, 32, 466685, tzinfo=Timezone('UTC')), 'last_scheduling_decision': datetime.datetime(2024, 6, 20, 10, 43, 39, 71854, tzinfo=Timezone('UTC')), 'dag_hash': 'bd2be89c788d9e9eea932b22a8865bd2', 'updated_at': datetime.datetime(2024, 6, 20, 10, 43, 39, 74003, tzinfo=Timezone('UTC')), 'dag_run_id': 73}]
(Background on this error at: https://sqlalche.me/e/14/gkpj); 5594)
[2024-06-20T10:43:39.654+0000] {local_task_job_runner.py:228} INFO - Task exited with return code 1
